<mujoco>

    <body name="fp3_link0" childclass="panda" >
      <inertial mass="0.629769" pos="-0.041018 -0.00014 0.049974"
        fullinertia="0.00315 0.00388 0.004285 8.2904e-7 0.00015 8.2299e-6"/>
        <geom class="visual" mesh="link0_visual"/>
        <!-- <geom class="collision" mesh="link0_collision"/> -->

        <body name="fp3_link1" pos="0 0 0.333">
            
            <inertial mass="4.970684" pos="0.003875 0.002081 -0.04762"
                fullinertia="0.70337 0.70661 0.0091170 -0.00013900 0.0067720 0.019169"/>
            <joint name="panda_joint1"/>
            
            <geom class="visual" mesh="link1_visual"/>
            <geom class="collision" mesh="link1_collision"/>

            <body name="fp3_link2" pos="0 0 0" quat="0.707107 -0.707107 0 0">
                
                <inertial mass="0.646926" pos="-0.003141 -0.02872 0.003495"
                    fullinertia="0.0079620 2.8110e-2 2.5995e-2 -3.925e-3 1.0254e-2 7.04e-4"/>
                <joint name="panda_joint2" range="-1.7628 1.7628" frictionloss="2"/>
                
                <geom class="visual" mesh="link2_visual"/>
                <geom class="collision" mesh="link2_collision"/>

                <body name="fp3_link3" pos="0 -0.316 0" quat="0.707107 0.707107 0 0">
                    
                    <inertial mass="3.228604" pos="2.7518e-2 3.9252e-2 -6.6502e-2"
                        fullinertia="3.7242e-2 3.6155e-2 1.083e-2 -4.761e-3 -1.1396e-2 -1.2805e-2"/>
                    <joint name="panda_joint3" range="-2.8973 2.8973" frictionloss="2"/>
                    
                    <geom class="visual" mesh="link3_visual"/>
                    <geom class="collision" mesh="link3_collision"/>

                    <body name="fp3_link4" pos="0.0825 0 0" quat="0.707107 0.707107 0 0">
                        
                        <inertial mass="3.587895" pos="-5.317e-2 1.04419e-1 2.7454e-2"
                            fullinertia="2.5853e-2 1.9552e-2 2.8323e-2 7.796e-3 -1.332e-3 8.641e-3"/>
                        <joint name="panda_joint4" range="-3.0718 -0.4" frictionloss="0.5"/>
                        
                        <geom class="visual" mesh="link4_visual"/>
                        <geom class="collision" mesh="link4_collision"/>

                        <body name="fp3_link5" pos="-0.0825 0.384 0" quat="0.707107 -0.707107 0 0">
                            
                            <inertial mass="1.225946" pos="-1.1953e-2 4.1065e-2 -3.8437e-2"
                                fullinertia="3.5549e-2 2.9474e-2 8.627e-3 -2.117e-3 -4.037e-3 2.29e-4"/>
                            <joint name="panda_joint5" range="-2.8973 2.8973" frictionloss="1"/>
                            
                            <geom class="visual" mesh="link5_visual"/>
                            <geom class="collision" mesh="link5_collision"/>

                            <body name="fp3_link6" pos="0 0 0" quat="0.707107 0.707107 0 0">
                                
                                <inertial mass="1.666555" pos="6.0149e-2 -1.4117e-2 -1.0517e-2"
                                    fullinertia="1.964e-3 4.354e-3 5.433e-3 1.09e-4 -1.158e-3 3.41e-4"/>
                                <joint name="panda_joint6" range="-1.6573 2.1127" frictionloss="0.5"/>
                                
                                <geom class="visual" mesh="link6_visual"/>
                                <geom class="collision" mesh="link6_collision"/>

                                <body name="fp3_link7" pos="0.088 0 0" euler='1.57 0 0.'>
                                    
                                    <inertial mass="7.35522e-01" pos="1.0517e-2 -4.252e-3 6.1597e-2"
                                        fullinertia="1.2516e-2 1.0027e-2 4.815e-3 -4.28e-4 -1.196e-3 -7.41e-4"/>
                                    <joint name="panda_joint7" range="-2.8973 2.8973" frictionloss="0.5"/>
                                    
                                    <geom class="visual" mesh="link7_visual"/>
                                    <geom class="collision" mesh="link7_collision"/>

                                    <site name='ft_sensor_site' pos='0 0 0.107' euler='0 0 -1.57'/>
                                    <include file="gripper.xml"/>
                                </body>
                            </body>
                        </body>
                    </body>
                </body>
            </body>
        </body>
    </body>
</mujoco>
