<mujoco>
<body name="hand" pos="0 0 0.107" euler="0 0 -0.785">
    <inertial mass="0.73" pos="-0.01 0 0.03" diaginertia="0.001 0.0025 0.0017"/>
    <geom class="visual" mesh="hand_visual"/>
    <geom class="collision" mesh="hand_collision"/>

    <body name="leftfinger" pos="0 0 0.03" quat="1 0 0 0">
        <inertial mass="0.015" pos="0 0 0" diaginertia="2.375e-6 2.375e-6 7.5e-7"/>
        <joint name="panda_finger_joint1"  axis="0 1 0" type="slide" range="0 0.04" damping="100" armature='5'/>
        <geom class="visual" mesh="finger_visual"/>
        <geom class="collision" mesh="finger_collision" mass="0.01"/>
    </body>

    <body name="rightfinger" pos="0 0 0.03" quat="1 0 0 0">
        <inertial mass="0.015" pos="0 0 0" diaginertia="2.375e-6 2.375e-6 7.5e-7"/>
        <joint name="panda_finger_joint2" axis="0 -1 0" type="slide" range="0 0.04" damping="100" armature='5'/>
        <geom quat="0 0 0 1" class="visual" mesh="finger_visual"/>
        <geom quat="0 0 0 1" class="collision" mesh="finger_collision" mass="0.01"/>
    </body>
</body>
</mujoco>